Workbook

Sheet Portada
B2: dovo | Modelo Financiero de Inversionista
B3: Fitness para DUOS · dovofit.com · Pre-seed · Mexico (MXN)
B5: SENSIBILIDAD #1 = CHURN. La racha del duo es la tesis: si el churn baja de ~12% a ~5%, el LTV y el LTV:CAC se multiplican. Es la palanca que mas mueve el valor del negocio.
B7: Unidad de negocio
B8: 1 DUO = 2 personas = 1 suscripcion
B9: Free (primeros 200 duos) -> Pro ($99 MXN/mes/duo) -> Premium
B10: Margen bruto objetivo > 80%
B12: Hito | C12: Conservador | D12: Base | E12: Agresivo
B13: MRR M12 | C13: =Hitos!C5 -> 1424.9363 | D13: =Hitos!D5 -> 7076.1979 | E13: =Hitos!E5 -> 29560.652
B14: MRR M24 | C14: =Hitos!C6 -> 6318.9015 | D14: =Hitos!D6 -> 32205.693 | E14: =Hitos!E6 -> 141072.23
B15: MRR M36 | C15: =Hitos!C7 -> 18039.405 | D15: =Hitos!D7 -> 108742.86 | E15: =Hitos!E7 -> 545243.75
B16: ARR M36 | C16: =Hitos!C8 -> 216472.86 | D16: =Hitos!D8 -> 1304914.4 | E16: =Hitos!E8 -> 6542925
B17: LTV:CAC (Base) | D17: ='Unit Economics'!C10 -> 350
B18: Payback (Base) | D18: ='Unit Economics'!C11 -> 906.4375
B20: Leyenda:
B21: Celda EDITABLE (input)
B22: Formula calculada
B23: Link a otra hoja
B25: Todas las cifras en MXN. Mercado e hitos = SUPUESTOS pre-seed, no garantias.

Sheet Supuestos
B2: Supuestos (celdas amarillas = editables)
B3: Cambia las celdas amarillas y todo el modelo se recalcula. Sensibilidad #1 = Churn mensual. Adquisicion (nuevos duos M1 y crecimiento MoM) esta calibrada para reproducir los hitos de MRR objetivo; conversion, churn, precio y costos son palancas de negocio editables.
B5: Variable | C5: Conservador | D5: Base | E5: Agresivo
B6: Nuevos duos / mes (M1) | C6: 33 | D6: 47 | E6: 87 | G6: Adquisicion inicial mes 1 (calibrado a hitos de MRR)
B7: Crecimiento MoM (nuevos) | C7: 0.08 | D7: 0.1 | E7: 0.115 | G7: Crecimiento mensual de los nuevos duos (calibrado a hitos)
B8: Conversion Free -> Pro | C8: 0.06 | D8: 0.12 | E8: 0.2 | G8: % de duos activos que pagan
B9: Churn mensual (pagos) | C9: 0.08 | D9: 0.05 | E9: 0.035 | G9: SENSIBILIDAD #1: la racha del duo
B10: Costo variable / duo / mes | C10: 25 | D10: 20 | E10: 15 | G10: Infra, pasarela, soporte por duo de pago
B11: CAC por duo | C11: 350 | D11: 250 | E11: 180 | G11: Costo de adquisicion por duo
B12: Precio / duo / mes | C12: 99 | D12: 99 | E12: 99 | G12: Plan Pro mensual por duo
B13: Mix anual (descuento) | C13: 0.1 | D13: 0.2 | E13: 0.3 | G13: % de pagos en plan anual con descuento
B14: Free iniciales (no pagan) | C14: 200 | D14: 200 | E14: 200 | G14: Primeros 200 duos en Free
B15: Descuento del plan anual | C15: 0.15 | D15: 0.15 | E15: 0.15 | G15: Descuento aplicado al precio anual
B17: ARPU efectivo = precio * (1 - mix_anual * descuento_anual). El plan anual reduce el ingreso mensual promedio por el descuento.

Sheet Proyeccion
A1: Proyeccion a 36 meses por escenario
A2: Todo referencia la hoja Supuestos. ARPU efectivo ajustado por mix anual. Free no paga; conversion aplica sobre activos por arriba de los Free iniciales.
A4: Escenario: Conservador
A5: Mes | B5: Nuevos duos | C5: Duos activos | D5: Duos de pago | E5: ARPU efectivo | F5: MRR | G5: ARR | H5: Costo var. total | I5: Margen bruto | J5: Margen %
A6: 1 | B6: =Supuestos!C6 -> 33 | C6: =B6 -> 33 | D6: =MAX(0,C6-Supuestos!C14)*Supuestos!C8 -> 0 | E6: =Supuestos!C12*(1-Supuestos!C13*Supuestos!C15) -> 97.515 | F6: =D6*E6 -> 0 | G6: =F6*12 -> 0 | H6: =D6*Supuestos!C10 -> 0 | I6: =F6-H6 -> 0 | J6: =IF(F6=0,0,I6/F6) -> 0
A7: 2 | B7: =B6*(1+Supuestos!C7) -> 35.64 | C7: =C6*(1-Supuestos!C9)+B7 -> 66 | D7: =MAX(0,C7-Supuestos!C14)*Supuestos!C8 -> 0 | E7: =Supuestos!C12*(1-Supuestos!C13*Supuestos!C15) -> 97.515 | F7: =D7*E7 -> 0 | G7: =F7*12 -> 0 | H7: =D7*Supuestos!C10 -> 0 | I7: =F7-H7 -> 0 | J7: =IF(F7=0,0,I7/F7) -> 0
A8: 3 | B8: =B7*(1+Supuestos!C7) -> 38.4912 | C8: =C7*(1-Supuestos!C9)+B8 -> 99.2112 | D8: =MAX(0,C8-Supuestos!C14)*Supuestos!C8 -> 0 | E8: =Supuestos!C12*(1-Supuestos!C13*Supuestos!C15) -> 97.515 | F8: =D8*E8 -> 0 | G8: =F8*12 -> 0 | H8: =D8*Supuestos!C10 -> 0 | I8: =F8-H8 -> 0 | J8: =IF(F8=0,0,I8/F8) -> 0
A9: 4 | B9: =B8*(1+Supuestos!C7) -> 41.570496 | C9: =C8*(1-Supuestos!C9)+B9 -> 132.8448 | D9: =MAX(0,C9-Supuestos!C14)*Supuestos!C8 -> 0 | E9: =Supuestos!C12*(1-Supuestos!C13*Supuestos!C15) -> 97.515 | F9: =D9*E9 -> 0 | G9: =F9*12 -> 0 | H9: =D9*Supuestos!C10 -> 0 | I9: =F9-H9 -> 0 | J9: =IF(F9=0,0,I9/F9) -> 0
A10: 5 | B10: =B9*(1+Supuestos!C7) -> 44.896136 | C10: =C9*(1-Supuestos!C9)+B10 -> 167.11335 | D10: =MAX(0,C10-Supuestos!C14)*Supuestos!C8 -> 0 | E10: =Supuestos!C12*(1-Supuestos!C13*Supuestos!C15) -> 97.515 | F10: =D10*E10 -> 0 | G10: =F10*12 -> 0 | H10: =D10*Supuestos!C10 -> 0 | I10: =F10-H10 -> 0 | J10: =IF(F10=0,0,I10/F10) -> 0
A11: 6 | B11: =B10*(1+Supuestos!C7) -> 48.487827 | C11: =C10*(1-Supuestos!C9)+B11 -> 202.23211 | D11: =MAX(0,C11-Supuestos!C14)*Supuestos!C8 -> 0.1339266 | E11: =Supuestos!C12*(1-Supuestos!C13*Supuestos!C15) -> 97.515 | F11: =D11*E11 -> 13.059853 | G11: =F11*12 -> 156.71823 | H11: =D11*Supuestos!C10 -> 3.3481651 | I11: =F11-H11 -> 9.7116877 | J11: =IF(F11=0,0,I11/F11) -> 0.74362919
A12: 7 | B12: =B11*(1+Supuestos!C7) -> 52.366853 | C12: =C11*(1-Supuestos!C9)+B12 -> 238.42039 | D12: =MAX(0,C12-Supuestos!C14)*Supuestos!C8 -> 2.3052236 | E12: =Supuestos!C12*(1-Supuestos!C13*Supuestos!C15) -> 97.515 | F12: =D12*E12 -> 224.79388 | G12: =F12*12 -> 2697.5266 | H12: =D12*Supuestos!C10 -> 57.630591 | I12: =F12-H12 -> 167.16329 | J12: =IF(F12=0,0,I12/F12) -> 0.74362919
A13: 8 | B13: =B12*(1+Supuestos!C7) -> 56.556201 | C13: =C12*(1-Supuestos!C9)+B13 -> 275.90296 | D13: =MAX(0,C13-Supuestos!C14)*Supuestos!C8 -> 4.5541778 | E13: =Supuestos!C12*(1-Supuestos!C13*Supuestos!C15) -> 97.515 | F13: =D13*E13 -> 444.10065 | G13: =F13*12 -> 5329.2078 | H13: =D13*Supuestos!C10 -> 113.85444 | I13: =F13-H13 -> 330.2462 | J13: =IF(F13=0,0,I13/F13) -> 0.74362919
A14: 9 | B14: =B13*(1+Supuestos!C7) -> 61.080697 | C14: =C13*(1-Supuestos!C9)+B14 -> 314.91142 | D14: =MAX(0,C14-Supuestos!C14)*Supuestos!C8 -> 6.8946854 | E14: =Supuestos!C12*(1-Supuestos!C13*Supuestos!C15) -> 97.515 | F14: =D14*E14 -> 672.33525 | G14: =F14*12 -> 8068.0229 | H14: =D14*Supuestos!C10 -> 172.36713 | I14: =F14-H14 -> 499.96811 | J14: =IF(F14=0,0,I14/F14) -> 0.74362919
A15: 10 | B15: =B14*(1+Supuestos!C7) -> 65.967153 | C15: =C14*(1-Supuestos!C9)+B15 -> 355.68566 | D15: =MAX(0,C15-Supuestos!C14)*Supuestos!C8 -> 9.3411397 | E15: =Supuestos!C12*(1-Supuestos!C13*Supuestos!C15) -> 97.515 | F15: =D15*E15 -> 910.90124 | G15: =F15*12 -> 10930.815 | H15: =D15*Supuestos!C10 -> 233.52849 | I15: =F15-H15 -> 677.37275 | J15: =IF(F15=0,0,I15/F15) -> 0.74362919
A16: 11 | B16: =B15*(1+Supuestos!C7) -> 71.244525 | C16: =C15*(1-Supuestos!C9)+B16 -> 398.47533 | D16: =MAX(0,C16-Supuestos!C14)*Supuestos!C8 -> 11.90852 | E16: =Supuestos!C12*(1-Supuestos!C13*Supuestos!C15) -> 97.515 | F16: =D16*E16 -> 1161.2593 | G16: =F16*12 -> 13935.112 | H16: =D16*Supuestos!C10 -> 297.713 | I16: =F16-H16 -> 863.54633 | J16: =IF(F16=0,0,I16/F16) -> 0.74362919
A17: 12 | B17: =B16*(1+Supuestos!C7) -> 76.944087 | C17: =C16*(1-Supuestos!C9)+B17 -> 443.54139 | D17: =MAX(0,C17-Supuestos!C14)*Supuestos!C8 -> 14.612484 | E17: =Supuestos!C12*(1-Supuestos!C13*Supuestos!C15) -> 97.515 | F17: =D17*E17 -> 1424.9363 | G17: =F17*12 -> 17099.236 | H17: =D17*Supuestos!C10 -> 365.31209 | I17: =F17-H17 -> 1059.6243 | J17: =IF(F17=0,0,I17/F17) -> 0.74362919
A18: 13 | B18: =B17*(1+Supuestos!C7) -> 83.099614 | C18: =C17*(1-Supuestos!C9)+B18 -> 491.1577 | D18: =MAX(0,C18-Supuestos!C14)*Supuestos!C8 -> 17.469462 | E18: =Supuestos!C12*(1-Supuestos!C13*Supuestos!C15) -> 97.515 | F18: =D18*E18 -> 1703.5346 | G18: =F18*12 -> 20442.415 | H18: =D18*Supuestos!C10 -> 436.73654 | I18: =F18-H18 -> 1266.798 | J18: =IF(F18=0,0,I18/F18) -> 0.74362919
A19: 14 | B19: =B18*(1+Supuestos!C7) -> 89.747583 | C19: =C18*(1-Supuestos!C9)+B19 -> 541.61266 | D19: =MAX(0,C19-Supuestos!C14)*Supuestos!C8 -> 20.49676 | E19: =Supuestos!C12*(1-Supuestos!C13*Supuestos!C15) -> 97.515 | F19: =D19*E19 -> 1998.7415 | G19: =F19*12 -> 23984.898 | H19: =D19*Supuestos!C10 -> 512.419 | I19: =F19-H19 -> 1486.3225 | J19: =IF(F19=0,0,I19/F19) -> 0.74362919
A20: 15 | B20: =B19*(1+Supuestos!C7) -> 96.92739 | C20: =C19*(1-Supuestos!C9)+B20 -> 595.21104 | D20: =MAX(0,C20-Supuestos!C14)*Supuestos!C8 -> 23.712662 | E20: =Supuestos!C12*(1-Supuestos!C13*Supuestos!C15) -> 97.515 | F20: =D20*E20 -> 2312.3403 | G20: =F20*12 -> 27748.083 | H20: =D20*Supuestos!C10 -> 592.81656 | I20: =F20-H20 -> 1719.5237 | J20: =IF(F20=0,0,I20/F20) -> 0.74362919
A21: 16 | B21: =B20*(1+Supuestos!C7) -> 104.68158 | C21: =C20*(1-Supuestos!C9)+B21 -> 652.27574 | D21: =MAX(0,C21-Supuestos!C14)*Supuestos!C8 -> 27.136544 | E21: =Supuestos!C12*(1-Supuestos!C13*Supuestos!C15) -> 97.515 | F21: =D21*E21 -> 2646.2201 | G21: =F21*12 -> 31754.641 | H21: =D21*Supuestos!C10 -> 678.41361 | I21: =F21-H21 -> 1967.8065 | J21: =IF(F21=0,0,I21/F21) -> 0.74362919
A22: 17 | B22: =B21*(1+Supuestos!C7) -> 113.05611 | C22: =C21*(1-Supuestos!C9)+B22 -> 713.14979 | D22: =MAX(0,C22-Supuestos!C14)*Supuestos!C8 -> 30.788987 | E22: =Supuestos!C12*(1-Supuestos!C13*Supuestos!C15) -> 97.515 | F22: =D22*E22 -> 3002.3881 | G22: =F22*12 -> 36028.657 | H22: =D22*Supuestos!C10 -> 769.72468 | I22: =F22-H22 -> 2232.6634 | J22: =IF(F22=0,0,I22/F22) -> 0.74362919
A23: 18 | B23: =B22*(1+Supuestos!C7) -> 122.1006 | C23: =C22*(1-Supuestos!C9)+B23 -> 778.1984 | D23: =MAX(0,C23-Supuestos!C14)*Supuestos!C8 -> 34.691904 | E23: =Supuestos!C12*(1-Supuestos!C13*Supuestos!C15) -> 97.515 | F23: =D23*E23 -> 3382.981 | G23: =F23*12 -> 40595.772 | H23: =D23*Supuestos!C10 -> 867.2976 | I23: =F23-H23 -> 2515.6834 | J23: =IF(F23=0,0,I23/F23) -> 0.74362919
A24: 19 | B24: =B23*(1+Supuestos!C7) -> 131.86864 | C24: =C23*(1-Supuestos!C9)+B24 -> 847.81117 | D24: =MAX(0,C24-Supuestos!C14)*Supuestos!C8 -> 38.86867 | E24: =Supuestos!C12*(1-Supuestos!C13*Supuestos!C15) -> 97.515 | F24: =D24*E24 -> 3790.2784 | G24: =F24*12 -> 45483.341 | H24: =D24*Supuestos!C10 -> 971.71676 | I24: =F24-H24 -> 2818.5616 | J24: =IF(F24=0,0,I24/F24) -> 0.74362919
A25: 20 | B25: =B24*(1+Supuestos!C7) -> 142.41813 | C25: =C24*(1-Supuestos!C9)+B25 -> 922.40441 | D25: =MAX(0,C25-Supuestos!C14)*Supuestos!C8 -> 43.344265 | E25: =Supuestos!C12*(1-Supuestos!C13*Supuestos!C15) -> 97.515 | F25: =D25*E25 -> 4226.716 | G25: =F25*12 -> 50720.592 | H25: =D25*Supuestos!C10 -> 1083.6066 | I25: =F25-H25 -> 3143.1094 | J25: =IF(F25=0,0,I25/F25) -> 0.74362919
A26: 21 | B26: =B25*(1+Supuestos!C7) -> 153.81159 | C26: =C25*(1-Supuestos!C9)+B26 -> 1002.4236 | D26: =MAX(0,C26-Supuestos!C14)*Supuestos!C8 -> 48.145419 | E26: =Supuestos!C12*(1-Supuestos!C13*Supuestos!C15) -> 97.515 | F26: =D26*E26 -> 4694.9005 | G26: =F26*12 -> 56338.806 | H26: =D26*Supuestos!C10 -> 1203.6355 | I26: =F26-H26 -> 3491.265 | J26: =IF(F26=0,0,I26/F26) -> 0.74362919
A27: 22 | B27: =B26*(1+Supuestos!C7) -> 166.11651 | C27: =C26*(1-Supuestos!C9)+B27 -> 1088.3463 | D27: =MAX(0,C27-Supuestos!C14)*Supuestos!C8 -> 53.300776 | E27: =Supuestos!C12*(1-Supuestos!C13*Supuestos!C15) -> 97.515 | F27: =D27*E27 -> 5197.6252 | G27: =F27*12 -> 62371.502 | H27: =D27*Supuestos!C10 -> 1332.5194 | I27: =F27-H27 -> 3865.1058 | J27: =IF(F27=0,0,I27/F27) -> 0.74362919
A28: 23 | B28: =B27*(1+Supuestos!C7) -> 179.40583 | C28: =C27*(1-Supuestos!C9)+B28 -> 1180.6844 | D28: =MAX(0,C28-Supuestos!C14)*Supuestos!C8 -> 58.841064 | E28: =Supuestos!C12*(1-Supuestos!C13*Supuestos!C15) -> 97.515 | F28: =D28*E28 -> 5737.8863 | G28: =F28*12 -> 68854.636 | H28: =D28*Supuestos!C10 -> 1471.0266 | I28: =F28-H28 -> 4266.8597 | J28: =IF(F28=0,0,I28/F28) -> 0.74362919
A29: 24 | B29: =B28*(1+Supuestos!C7) -> 193.7583 | C29: =C28*(1-Supuestos!C9)+B29 -> 1279.9879 | D29: =MAX(0,C29-Supuestos!C14)*Supuestos!C8 -> 64.799277 | E29: =Supuestos!C12*(1-Supuestos!C13*Supuestos!C15) -> 97.515 | F29: =D29*E29 -> 6318.9015 | G29: =F29*12 -> 75826.818 | H29: =D29*Supuestos!C10 -> 1619.9819 | I29: =F29-H29 -> 4698.9196 | J29: =IF(F29=0,0,I29/F29) -> 0.74362919
A30: 25 | B30: =B29*(1+Supuestos!C7) -> 209.25896 | C30: =C29*(1-Supuestos!C9)+B30 -> 1386.8479 | D30: =MAX(0,C30-Supuestos!C14)*Supuestos!C8 -> 71.210873 | E30: =Supuestos!C12*(1-Supuestos!C13*Supuestos!C15) -> 97.515 | F30: =D30*E30 -> 6944.1282 | G30: =F30*12 -> 83329.539 | H30: =D30*Supuestos!C10 -> 1780.2718 | I30: =F30-H30 -> 5163.8564 | J30: =IF(F30=0,0,I30/F30) -> 0.74362919
A31: 26 | B31: =B30*(1+Supuestos!C7) -> 225.99968 | C31: =C30*(1-Supuestos!C9)+B31 -> 1501.8997 | D31: =MAX(0,C31-Supuestos!C14)*Supuestos!C8 -> 78.113984 | E31: =Supuestos!C12*(1-Supuestos!C13*Supuestos!C15) -> 97.515 | F31: =D31*E31 -> 7617.2851 | G31: =F31*12 -> 91407.421 | H31: =D31*Supuestos!C10 -> 1952.8496 | I31: =F31-H31 -> 5664.4355 | J31: =IF(F31=0,0,I31/F31) -> 0.74362919
A32: 27 | B32: =B31*(1+Supuestos!C7) -> 244.07966 | C32: =C31*(1-Supuestos!C9)+B32 -> 1625.8274 | D32: =MAX(0,C32-Supuestos!C14)*Supuestos!C8 -> 85.549644 | E32: =Supuestos!C12*(1-Supuestos!C13*Supuestos!C15) -> 97.515 | F32: =D32*E32 -> 8342.3736 | G32: =F32*12 -> 100108.48 | H32: =D32*Supuestos!C10 -> 2138.7411 | I32: =F32-H32 -> 6203.6325 | J32: =IF(F32=0,0,I32/F32) -> 0.74362919
A33: 28 | B33: =B32*(1+Supuestos!C7) -> 263.60603 | C33: =C32*(1-Supuestos!C9)+B33 -> 1759.3672 | D33: =MAX(0,C33-Supuestos!C14)*Supuestos!C8 -> 93.562034 | E33: =Supuestos!C12*(1-Supuestos!C13*Supuestos!C15) -> 97.515 | F33: =D33*E33 -> 9123.7018 | G33: =F33*12 -> 109484.42 | H33: =D33*Supuestos!C10 -> 2339.0509 | I33: =F33-H33 -> 6784.6509 | J33: =IF(F33=0,0,I33/F33) -> 0.74362919
A34: 29 | B34: =B33*(1+Supuestos!C7) -> 284.69451 | C34: =C33*(1-Supuestos!C9)+B34 -> 1903.3124 | D34: =MAX(0,C34-Supuestos!C14)*Supuestos!C8 -> 102.19874 | E34: =Supuestos!C12*(1-Supuestos!C13*Supuestos!C15) -> 97.515 | F34: =D34*E34 -> 9965.9104 | G34: =F34*12 -> 119590.92 | H34: =D34*Supuestos!C10 -> 2554.9686 | I34: =F34-H34 -> 7410.9418 | J34: =IF(F34=0,0,I34/F34) -> 0.74362919
A35: 30 | B35: =B34*(1+Supuestos!C7) -> 307.47007 | C35: =C34*(1-Supuestos!C9)+B35 -> 2058.5175 | D35: =MAX(0,C35-Supuestos!C14)*Supuestos!C8 -> 111.51105 | E35: =Supuestos!C12*(1-Supuestos!C13*Supuestos!C15) -> 97.515 | F35: =D35*E35 -> 10874 | G35: =F35*12 -> 130488 | H35: =D35*Supuestos!C10 -> 2787.7762 | I35: =F35-H35 -> 8086.2236 | J35: =IF(F35=0,0,I35/F35) -> 0.74362919
A36: 31 | B36: =B35*(1+Supuestos!C7) -> 332.06768 | C36: =C35*(1-Supuestos!C9)+B36 -> 2225.9037 | D36: =MAX(0,C36-Supuestos!C14)*Supuestos!C8 -> 121.55422 | E36: =Supuestos!C12*(1-Supuestos!C13*Supuestos!C15) -> 97.515 | F36: =D36*E36 -> 11853.36 | G36: =F36*12 -> 142240.32 | H36: =D36*Supuestos!C10 -> 3038.8556 | I36: =F36-H36 -> 8814.5046 | J36: =IF(F36=0,0,I36/F36) -> 0.74362919
A37: 32 | B37: =B36*(1+Supuestos!C7) -> 358.63309 | C37: =C36*(1-Supuestos!C9)+B37 -> 2406.4645 | D37: =MAX(0,C37-Supuestos!C14)*Supuestos!C8 -> 132.38787 | E37: =Supuestos!C12*(1-Supuestos!C13*Supuestos!C15) -> 97.515 | F37: =D37*E37 -> 12909.803 | G37: =F37*12 -> 154917.64 | H37: =D37*Supuestos!C10 -> 3309.6968 | I37: =F37-H37 -> 9600.1065 | J37: =IF(F37=0,0,I37/F37) -> 0.74362919
A38: 33 | B38: =B37*(1+Supuestos!C7) -> 387.32374 | C38: =C37*(1-Supuestos!C9)+B38 -> 2601.2711 | D38: =MAX(0,C38-Supuestos!C14)*Supuestos!C8 -> 144.07627 | E38: =Supuestos!C12*(1-Supuestos!C13*Supuestos!C15) -> 97.515 | F38: =D38*E38 -> 14049.597 | G38: =F38*12 -> 168595.17 | H38: =D38*Supuestos!C10 -> 3601.9067 | I38: =F38-H38 -> 10447.69 | J38: =IF(F38=0,0,I38/F38) -> 0.74362919
A39: 34 | B39: =B38*(1+Supuestos!C7) -> 418.30964 | C39: =C38*(1-Supuestos!C9)+B39 -> 2811.4791 | D39: =MAX(0,C39-Supuestos!C14)*Supuestos!C8 -> 156.68874 | E39: =Supuestos!C12*(1-Supuestos!C13*Supuestos!C15) -> 97.515 | F39: =D39*E39 -> 15279.503 | G39: =F39*12 -> 183354.03 | H39: =D39*Supuestos!C10 -> 3917.2186 | I39: =F39-H39 -> 11362.284 | J39: =IF(F39=0,0,I39/F39) -> 0.74362919
A40: 35 | B40: =B39*(1+Supuestos!C7) -> 451.77441 | C40: =C39*(1-Supuestos!C9)+B40 -> 3038.3351 | D40: =MAX(0,C40-Supuestos!C14)*Supuestos!C8 -> 170.30011 | E40: =Supuestos!C12*(1-Supuestos!C13*Supuestos!C15) -> 97.515 | F40: =D40*E40 -> 16606.815 | G40: =F40*12 -> 199281.78 | H40: =D40*Supuestos!C10 -> 4257.5027 | I40: =F40-H40 -> 12349.312 | J40: =IF(F40=0,0,I40/F40) -> 0.74362919
A41: 36 | B41: =B40*(1+Supuestos!C7) -> 487.91636 | C41: =C40*(1-Supuestos!C9)+B41 -> 3283.1847 | D41: =MAX(0,C41-Supuestos!C14)*Supuestos!C8 -> 184.99108 | E41: =Supuestos!C12*(1-Supuestos!C13*Supuestos!C15) -> 97.515 | F41: =D41*E41 -> 18039.405 | G41: =F41*12 -> 216472.86 | H41: =D41*Supuestos!C10 -> 4624.777 | I41: =F41-H41 -> 13414.628 | J41: =IF(F41=0,0,I41/F41) -> 0.74362919
...

Sheet Unit Economics
B2: Unit Economics por escenario
B3: LTV = (ARPU_ef * margen%) / churn. Payback = CAC / (ARPU_ef * margen%). Margen% en estado estable (M36).
B5: Metrica | C5: Conservador | D5: Base | E5: Agresivo
B6: ARPU efectivo (MXN/mes) | C6: =Proyeccion!E41 -> 97.515 | D6: =Proyeccion!E80 -> 96.03 | E6: =Proyeccion!E119 -> 94.545
B7: Margen bruto % | C7: =Proyeccion!J41 -> 0.74362919 | D7: =Proyeccion!J80 -> 0.79173175 | E7: =Proyeccion!J119 -> 0.84134539
B8: Churn mensual | C8: =Supuestos!C9 -> 0.08 | D8: =Supuestos!D9 -> 0.05 | E8: =Supuestos!E9 -> 0.035
B9: Contribucion / duo / mes | C9: =C6*C7 -> 72.515 | D9: =D6*D7 -> 76.03 | E9: =E6*E7 -> 79.545
B10: CAC por duo (MXN) | C10: =Supuestos!C11 -> 350 | D10: =Supuestos!D11 -> 250 | E10: =Supuestos!E11 -> 180
B11: LTV (MXN) | C11: =C9/C8 -> 906.4375 | D11: =D9/D8 -> 1520.6 | E11: =E9/E8 -> 2272.7143
B12: LTV : CAC | C12: =C11/C10 -> 2.5898214 | D12: =D11/D10 -> 6.0824 | E12: =E11/E10 -> 12.62619
B13: Payback (meses) | C13: =C10/C9 -> 4.8265876 | D13: =D10/D9 -> 3.2881757 | E13: =E10/E9 -> 2.2628701
B15: Base esperado: LTV ~$1,512 MXN, LTV:CAC ~6.0x, payback ~3.3 meses. La sensibilidad mas fuerte es el churn.
B17: Sensibilidad: LTV (Base) vs churn mensual
B18: Churn mensual | C18: LTV (MXN)
B19: 0.12 | C19: =D9/B19 -> 633.58333 | E19: Misma contribucion/duo del escenario Base; solo cambia el churn. Bajar churn de 12% a 5% mas que duplica el LTV.
B20: 0.08 | C20: =D9/B20 -> 950.375
B21: 0.06 | C21: =D9/B21 -> 1267.1667
B22: 0.05 | C22: =D9/B22 -> 1520.6
B23: 0.04 | C23: =D9/B23 -> 1900.75
B24: 0.035 | C24: =D9/B24 -> 2172.2857

Sheet Mercado
B2: Mercado Mexico [SUPUESTOS]
B3: Cifras de mercado son SUPUESTOS pre-seed con fines de dimensionamiento, no proyecciones. Unidad = DUO (2 personas).
B5: Nivel | C5: Duos | D5: Personas (~x2)
B6: TAM (total) | C6: 4500000 | D6: =C6*2 -> 9000000 | F6: Total de duos fitness potenciales en MX (~8-10M personas activas)
B7: SAM (alcanzable) | C7: 875000 | D7: =C7*2 -> 1750000 | F7: Segmento alcanzable: smartphone + intencion de entrenar en pareja/duo
B8: SOM 36m (objetivo) | C8: 15000 | D8: =C8*2 -> 30000 | F8: Captura realista a 36 meses (rango 5K-25K duos)
B10: SOM / SAM | C10: =C8/C7 -> 0.017142857
B11: SAM / TAM | C11: =C7/C6 -> 0.19444444
B12: SOM (duos) Base @ M36 | C12: =Proyeccion!C80 -> 9636.5357 | F12: Duos activos del escenario Base en M36 (link a Proyeccion) para comparar vs SOM supuesto.
B14: Rangos de referencia: TAM ~4-5M duos | SAM ~750K-1M duos | SOM 36m ~5K-25K duos. Ajustables arriba.

Sheet Hitos
B2: Hitos de MRR / ARR por escenario
B3: Todo referencia la hoja Proyeccion (links verdes). Cambia Supuestos y los hitos se mueven.
B4: Hito | C4: Conservador | D4: Base | E4: Agresivo
B5: MRR M12 | C5: =Proyeccion!F17 -> 1424.9363 | D5: =Proyeccion!F56 -> 7076.1979 | E5: =Proyeccion!F95 -> 29560.652 | G5: Guia objetivo: MRR M12 ~1.4K / 6.9K / 26.8K
B6: MRR M24 | C6: =Proyeccion!F29 -> 6318.9015 | D6: =Proyeccion!F68 -> 32205.693 | E6: =Proyeccion!F107 -> 141072.23 | G6: MRR M24 ~6.3K / 36.7K / 182K
B7: MRR M36 | C7: =Proyeccion!F41 -> 18039.405 | D7: =Proyeccion!F80 -> 108742.86 | E7: =Proyeccion!F119 -> 545243.75 | G7: MRR M36 ~17.2K / 109K / 478K
B8: ARR M36 | C8: =Proyeccion!G41 -> 216472.86 | D8: =Proyeccion!G80 -> 1304914.4 | E8: =Proyeccion!G119 -> 6542925 | G8: ARR M36 ~207K / 1.31M / 5.74M
B11: Duos de pago por hito
B12: Hito | C12: Conservador | D12: Base | E12: Agresivo
B13: Duos pago M12 | C13: =Proyeccion!D17 -> 14.612484 | D13: =Proyeccion!D56 -> 73.687368 | E13: =Proyeccion!D95 -> 312.66225
B14: Duos pago M24 | C14: =Proyeccion!D29 -> 64.799277 | D14: =Proyeccion!D68 -> 335.37116 | E14: =Proyeccion!D107 -> 1492.1173
B15: Duos pago M36 | C15: =Proyeccion!D41 -> 184.99108 | D15: =Proyeccion!D80 -> 1132.3843 | E15: =Proyeccion!D119 -> 5767.0289
